[2022-01-11 20:10:00,898] {taskinstance.py:1035} INFO - Dependencies all met for <TaskInstance: verificacao_log.send_email scheduled__2022-01-11T20:00:00+00:00 [queued]>
[2022-01-11 20:10:00,909] {taskinstance.py:1035} INFO - Dependencies all met for <TaskInstance: verificacao_log.send_email scheduled__2022-01-11T20:00:00+00:00 [queued]>
[2022-01-11 20:10:00,909] {taskinstance.py:1241} INFO - 
--------------------------------------------------------------------------------
[2022-01-11 20:10:00,909] {taskinstance.py:1242} INFO - Starting attempt 1 of 1
[2022-01-11 20:10:00,910] {taskinstance.py:1243} INFO - 
--------------------------------------------------------------------------------
[2022-01-11 20:10:00,922] {taskinstance.py:1262} INFO - Executing <Task(EmailOperator): send_email> on 2022-01-11 20:00:00+00:00
[2022-01-11 20:10:00,927] {standard_task_runner.py:52} INFO - Started process 6466 to run task
[2022-01-11 20:10:00,930] {standard_task_runner.py:76} INFO - Running: ['***', 'tasks', 'run', 'verificacao_log', 'send_email', 'scheduled__2022-01-11T20:00:00+00:00', '--job-id', '853', '--raw', '--subdir', 'DAGS_FOLDER/my_dag.py', '--cfg-path', '/tmp/tmpc6pxv2qu', '--error-file', '/tmp/tmp09rzc0mg']
[2022-01-11 20:10:00,931] {standard_task_runner.py:77} INFO - Job 853: Subtask send_email
[2022-01-11 20:10:00,970] {logging_mixin.py:109} INFO - Running <TaskInstance: verificacao_log.send_email scheduled__2022-01-11T20:00:00+00:00 [running]> on host e382db28423e
[2022-01-11 20:10:01,021] {taskinstance.py:1429} INFO - Exporting the following env vars:
AIRFLOW_CTX_DAG_OWNER=***
AIRFLOW_CTX_DAG_ID=verificacao_log
AIRFLOW_CTX_TASK_ID=send_email
AIRFLOW_CTX_EXECUTION_DATE=2022-01-11T20:00:00+00:00
AIRFLOW_CTX_DAG_RUN_ID=scheduled__2022-01-11T20:00:00+00:00
[2022-01-11 20:10:01,030] {warnings.py:110} WARNING - /home/***/.local/lib/python3.7/site-packages/***/utils/email.py:102: PendingDeprecationWarning: Fetching SMTP credentials from configuration variables will be deprecated in a future release. Please set credentials using a connection instead.
  send_mime_email(e_from=smtp_mail_from, e_to=recipients, mime_msg=msg, conn_id=conn_id, dryrun=dryrun)

[2022-01-11 20:10:01,031] {configuration.py:381} WARNING - section/key [smtp/smtp_user] not found in config
[2022-01-11 20:10:01,031] {email.py:208} INFO - Email alerting: attempt 1
[2022-01-11 20:10:01,031] {taskinstance.py:1703} ERROR - Task failed with exception
Traceback (most recent call last):
  File "/home/airflow/.local/lib/python3.7/site-packages/airflow/models/taskinstance.py", line 1332, in _run_raw_task
    self._execute_task_with_callbacks(context)
  File "/home/airflow/.local/lib/python3.7/site-packages/airflow/models/taskinstance.py", line 1458, in _execute_task_with_callbacks
    result = self._execute_task(context, self.task)
  File "/home/airflow/.local/lib/python3.7/site-packages/airflow/models/taskinstance.py", line 1514, in _execute_task
    result = execute_callable(context=context)
  File "/home/airflow/.local/lib/python3.7/site-packages/airflow/operators/email.py", line 88, in execute
    conn_id=self.conn_id,
  File "/home/airflow/.local/lib/python3.7/site-packages/airflow/utils/email.py", line 66, in send_email
    **kwargs,
  File "/home/airflow/.local/lib/python3.7/site-packages/airflow/utils/email.py", line 102, in send_email_smtp
    send_mime_email(e_from=smtp_mail_from, e_to=recipients, mime_msg=msg, conn_id=conn_id, dryrun=dryrun)
  File "/home/airflow/.local/lib/python3.7/site-packages/airflow/utils/email.py", line 210, in send_mime_email
    conn = _get_smtp_connection(smtp_host, smtp_port, smtp_timeout, smtp_ssl)
  File "/home/airflow/.local/lib/python3.7/site-packages/airflow/utils/email.py", line 244, in _get_smtp_connection
    else smtplib.SMTP(host=host, port=port, timeout=timeout)
  File "/usr/local/lib/python3.7/smtplib.py", line 251, in __init__
    (code, msg) = self.connect(host, port)
  File "/usr/local/lib/python3.7/smtplib.py", line 336, in connect
    self.sock = self._get_socket(host, port, self.timeout)
  File "/usr/local/lib/python3.7/smtplib.py", line 307, in _get_socket
    self.source_address)
  File "/usr/local/lib/python3.7/socket.py", line 728, in create_connection
    raise err
  File "/usr/local/lib/python3.7/socket.py", line 716, in create_connection
    sock.connect(sa)
OSError: [Errno 99] Cannot assign requested address
[2022-01-11 20:10:01,044] {taskinstance.py:1280} INFO - Marking task as FAILED. dag_id=verificacao_log, task_id=send_email, execution_date=20220111T200000, start_date=20220111T201000, end_date=20220111T201001
[2022-01-11 20:10:01,056] {standard_task_runner.py:91} ERROR - Failed to execute job 853 for task send_email
Traceback (most recent call last):
  File "/home/airflow/.local/lib/python3.7/site-packages/airflow/task/task_runner/standard_task_runner.py", line 85, in _start_by_fork
    args.func(args, dag=self.dag)
  File "/home/airflow/.local/lib/python3.7/site-packages/airflow/cli/cli_parser.py", line 48, in command
    return func(*args, **kwargs)
  File "/home/airflow/.local/lib/python3.7/site-packages/airflow/utils/cli.py", line 92, in wrapper
    return f(*args, **kwargs)
  File "/home/airflow/.local/lib/python3.7/site-packages/airflow/cli/commands/task_command.py", line 292, in task_run
    _run_task_by_selected_method(args, dag, ti)
  File "/home/airflow/.local/lib/python3.7/site-packages/airflow/cli/commands/task_command.py", line 107, in _run_task_by_selected_method
    _run_raw_task(args, ti)
  File "/home/airflow/.local/lib/python3.7/site-packages/airflow/cli/commands/task_command.py", line 184, in _run_raw_task
    error_file=args.error_file,
  File "/home/airflow/.local/lib/python3.7/site-packages/airflow/utils/session.py", line 70, in wrapper
    return func(*args, session=session, **kwargs)
  File "/home/airflow/.local/lib/python3.7/site-packages/airflow/models/taskinstance.py", line 1332, in _run_raw_task
    self._execute_task_with_callbacks(context)
  File "/home/airflow/.local/lib/python3.7/site-packages/airflow/models/taskinstance.py", line 1458, in _execute_task_with_callbacks
    result = self._execute_task(context, self.task)
  File "/home/airflow/.local/lib/python3.7/site-packages/airflow/models/taskinstance.py", line 1514, in _execute_task
    result = execute_callable(context=context)
  File "/home/airflow/.local/lib/python3.7/site-packages/airflow/operators/email.py", line 88, in execute
    conn_id=self.conn_id,
  File "/home/airflow/.local/lib/python3.7/site-packages/airflow/utils/email.py", line 66, in send_email
    **kwargs,
  File "/home/airflow/.local/lib/python3.7/site-packages/airflow/utils/email.py", line 102, in send_email_smtp
    send_mime_email(e_from=smtp_mail_from, e_to=recipients, mime_msg=msg, conn_id=conn_id, dryrun=dryrun)
  File "/home/airflow/.local/lib/python3.7/site-packages/airflow/utils/email.py", line 210, in send_mime_email
    conn = _get_smtp_connection(smtp_host, smtp_port, smtp_timeout, smtp_ssl)
  File "/home/airflow/.local/lib/python3.7/site-packages/airflow/utils/email.py", line 244, in _get_smtp_connection
    else smtplib.SMTP(host=host, port=port, timeout=timeout)
  File "/usr/local/lib/python3.7/smtplib.py", line 251, in __init__
    (code, msg) = self.connect(host, port)
  File "/usr/local/lib/python3.7/smtplib.py", line 336, in connect
    self.sock = self._get_socket(host, port, self.timeout)
  File "/usr/local/lib/python3.7/smtplib.py", line 307, in _get_socket
    self.source_address)
  File "/usr/local/lib/python3.7/socket.py", line 728, in create_connection
    raise err
  File "/usr/local/lib/python3.7/socket.py", line 716, in create_connection
    sock.connect(sa)
OSError: [Errno 99] Cannot assign requested address
[2022-01-11 20:10:01,102] {local_task_job.py:154} INFO - Task exited with return code 1
[2022-01-11 20:10:01,129] {local_task_job.py:264} INFO - 0 downstream tasks scheduled from follow-on schedule check
